Workbook

Sheet clinical_ann_with_alleles_22.12
A1: Clinical Annotation ID | B1: Variant/Haplotypes | C1: Gene | D1: Level of Evidence | E1: Level Override | F1: Level Modifiers | G1: Score | H1: Phenotype Category | I1: PMID Count | J1: Evidence Count | K1: Drug(s) | L1: Phenotype(s) | M1: Latest History Date (YYYY-MM-DD) | N1: URL | O1: Clinical Annotation ID | P1: Genotype/Allele | Q1: Annotation Text | R1: Allele Function
A2: 1448522784 | B2: rs9304742 | C2: ZNF816 | D2: 3 | E2: . | F2: . | G2: 2.5 | H2: Efficacy | I2: 1 | J2: 1 | K2: Tumor necrosis factor alpha (TNF-alpha) inhibitors | L2: Psoriasis | M2: 44279 | N2: https://www.pharmgkb.org/clinicalAnnotation/1448522784 | O2: 1448522784 | P2: CC | Q2: Patients with the CC genotype and psoriasis may have a poorer response to treatment with anti-TNF drugs as compared to patients with the CT or TT genotype. Other genetic and clinical factors may also influence response to anti-TNF drugs. | R2: .
A3: 1448522784 | B3: rs9304742 | C3: ZNF816 | D3: 3 | E3: . | F3: . | G3: 2.5 | H3: Efficacy | I3: 1 | J3: 1 | K3: Tumor necrosis factor alpha (TNF-alpha) inhibitors | L3: Psoriasis | M3: 44279 | N3: https://www.pharmgkb.org/clinicalAnnotation/1448522784 | O3: 1448522784 | P3: CT | Q3: Patients with the CT genotype and psoriasis may have a better response to treatment with anti-TNF drugs as compared to patients with the CC genotype. Other genetic and clinical factors may also influence response to anti-TNF drugs. | R3: .
A4: 1448522784 | B4: rs9304742 | C4: ZNF816 | D4: 3 | E4: . | F4: . | G4: 2.5 | H4: Efficacy | I4: 1 | J4: 1 | K4: Tumor necrosis factor alpha (TNF-alpha) inhibitors | L4: Psoriasis | M4: 44279 | N4: https://www.pharmgkb.org/clinicalAnnotation/1448522784 | O4: 1448522784 | P4: TT | Q4: Patients with the TT genotype and psoriasis may have a better response to treatment with anti-TNF drugs as compared to patients with the CC genotype. Other genetic and clinical factors may also influence response to anti-TNF drugs. | R4: .
A5: 1183614711 | B5: rs1344706 | C5: ZNF804A | D5: 3 | E5: . | F5: . | G5: 2 | H5: Efficacy | I5: 1 | J5: 1 | K5: antipsychotics | L5: Schizophrenia | M5: 44279 | N5: https://www.pharmgkb.org/clinicalAnnotation/1183614711 | O5: 1183614711 | P5: AA | Q5: Patients with the AA genotype and schizophrenia may have a poorer response when treated with antipsychotics as compared to patients with the AC or CC genotype. Other genetic and clinical factors may also influence response to antipsychotics. | R5: .
A6: 1183614711 | B6: rs1344706 | C6: ZNF804A | D6: 3 | E6: . | F6: . | G6: 2 | H6: Efficacy | I6: 1 | J6: 1 | K6: antipsychotics | L6: Schizophrenia | M6: 44279 | N6: https://www.pharmgkb.org/clinicalAnnotation/1183614711 | O6: 1183614711 | P6: AC | Q6: Patients with the AC genotype and schizophrenia may have a better response when treated with antipsychotics as compared to patients with the AA genotype. Other genetic and clinical factors may also influence response to antipsychotics. | R6: .
A7: 1183614711 | B7: rs1344706 | C7: ZNF804A | D7: 3 | E7: . | F7: . | G7: 2 | H7: Efficacy | I7: 1 | J7: 1 | K7: antipsychotics | L7: Schizophrenia | M7: 44279 | N7: https://www.pharmgkb.org/clinicalAnnotation/1183614711 | O7: 1183614711 | P7: CC | Q7: Patients with the CC genotype and schizophrenia may have a better response when treated with antipsychotics as compared to patients with the AA genotype. Other genetic and clinical factors may also influence response to antipsychotics. | R7: .
A8: 1449144346 | B8: rs62200793 | C8: ZNF804A | D8: 3 | E8: . | F8: . | G8: 0 | H8: Efficacy | I8: 1 | J8: 1 | K8: lithium | L8: Bipolar Disorder | M8: 44279 | N8: https://www.pharmgkb.org/clinicalAnnotation/1449144346 | O8: 1449144346 | P8: CC | Q8: Patients with the CC genotype and bipolar affective disorder may have a decreased response to lithium as compared to patients with the CT or TT genotypes. Other genetic and clinical factors may also influence a patient's response to lithium when treating bipolar affective disorder. | R8: .
A9: 1449144346 | B9: rs62200793 | C9: ZNF804A | D9: 3 | E9: . | F9: . | G9: 0 | H9: Efficacy | I9: 1 | J9: 1 | K9: lithium | L9: Bipolar Disorder | M9: 44279 | N9: https://www.pharmgkb.org/clinicalAnnotation/1449144346 | O9: 1449144346 | P9: CT | Q9: Patients with the CT genotype and bipolar affective disorder may have a decreased response to lithium as compared to patients with the TT genotype, but an increased response as compared to patients with the CC genotype. Other genetic and clinical factors may also influence a patient's response to lithium when treating bipolar affective disorder. | R9: .
A10: 1449144346 | B10: rs62200793 | C10: ZNF804A | D10: 3 | E10: . | F10: . | G10: 0 | H10: Efficacy | I10: 1 | J10: 1 | K10: lithium | L10: Bipolar Disorder | M10: 44279 | N10: https://www.pharmgkb.org/clinicalAnnotation/1449144346 | O10: 1449144346 | P10: TT | Q10: Patients with the TT genotype and bipolar affective disorder may have an increased response to lithium as compared to patients with the CT or CC genotypes. Other genetic and clinical factors may also influence a patient's response to lithium when treating bipolar affective disorder. | R10: .
A11: 1451403476 | B11: rs7597593 | C11: ZNF804A | D11: 3 | E11: . | F11: . | G11: 2 | H11: Toxicity | I11: 1 | J11: 1 | K11: opioids | L11: Opioid-Related Disorders | M11: 44291 | N11: https://www.pharmgkb.org/clinicalAnnotation/1451403476 | O11: 1451403476 | P11: CC | Q11: Patients with the rs7597593 CC genotype may have an increased risk of developing opioid dependence when exposed to opioids as compared to patients with the CT or TT genotypes. Other genetic and clinical factors may also influence risk of developing opioid dependence. | R11: .
A12: 1451403476 | B12: rs7597593 | C12: ZNF804A | D12: 3 | E12: . | F12: . | G12: 2 | H12: Toxicity | I12: 1 | J12: 1 | K12: opioids | L12: Opioid-Related Disorders | M12: 44291 | N12: https://www.pharmgkb.org/clinicalAnnotation/1451403476 | O12: 1451403476 | P12: CT | Q12: Patients with the rs7597593 CT genotype may have a decreased risk of developing opioid dependence when exposed to opioids as compared to patients with the CC genotype. Other genetic and clinical factors may also influence risk of developing opioid dependence. | R12: .
A13: 1451403476 | B13: rs7597593 | C13: ZNF804A | D13: 3 | E13: . | F13: . | G13: 2 | H13: Toxicity | I13: 1 | J13: 1 | K13: opioids | L13: Opioid-Related Disorders | M13: 44291 | N13: https://www.pharmgkb.org/clinicalAnnotation/1451403476 | O13: 1451403476 | P13: TT | Q13: Patients with the rs7597593 TT genotype may have a decreased risk of developing opioid dependence when exposed to opioids as compared to patients with the CC genotype. Other genetic and clinical factors may also influence risk of developing opioid dependence. | R13: .
... A121: 1449718331 | B121: rs25487 | C121: XRCC1 | D121: 3 | E121: . | F121: . | G121: 2.75 | H121: Toxicity | I121: 1 | J121: 1 | K121: cyclophosphamide;doxorubicin;fluorouracil | L121: Breast Neoplasms | M121: 44279 | N121: https://www.pharmgkb.org/clinicalAnnotation/1449718331 | O121: 1449718331 | P121: TT | Q121: Patients with the TT genotype and breast cancer may have an increased risk for nausea when treated with cyclophosphamide, doxorubicin and fluorouracil (FAC) as compared to patients with the CC genotype. Other genetic and clinical factors may also influence risk for nausea in patients taking FAC chemotherapy. | R121: .
A122: 655386657 | B122: rs25487 | C122: XRCC1 | D122: 2B | E122: . | F122: . | G122: 11.25 | H122: Efficacy | I122: 16 | J122: 19 | K122: Platinum compounds | L122: Neoplasms | M122: 44279 | N122: https://www.pharmgkb.org/clinicalAnnotation/655386657 | O122: 655386657 | P122: CC | Q122: Patients with cancer and the rs25487 CC genotype may have increased response when treated with platinum-based therapies as compared to patients with the CT or TT genotype. However, conflicting evidence has been reported. Other genetic and clinical factors may also influence response to platinum-based regimens. | R122: .
A123: 655386657 | B123: rs25487 | C123: XRCC1 | D123: 2B | E123: . | F123: . | G123: 11.25 | H123: Efficacy | I123: 16 | J123: 19 | K123: Platinum compounds | L123: Neoplasms | M123: 44279 | N123: https://www.pharmgkb.org/clinicalAnnotation/655386657 | O123: 655386657 | P123: CT | Q123: Patients with cancer and the rs25487 CT genotype may have decreased response when treated with platinum-based therapies as compared to patients with the CC genotype. However, conflicting evidence has been reported. Other genetic and clinical factors may also influence response to platinum-based regimens. | R123: .
A124: 655386657 | B124: rs25487 | C124: XRCC1 | D124: 2B | E124: . | F124: . | G124: 11.25 | H124: Efficacy | I124: 16 | J124: 19 | K124: Platinum compounds | L124: Neoplasms | M124: 44279 | N124: https://www.pharmgkb.org/clinicalAnnotation/655386657 | O124: 655386657 | P124: TT | Q124: Patients with cancer and the rs25487 TT genotype may have decreased response when treated with platinum-based therapies as compared to patients with the CC genotype. However, conflicting evidence has been reported. Other genetic and clinical factors may also influence response to platinum-based regimens. | R124: .
A125: 1449003956 | B125: rs11125883 | C125: XPO1 | D125: 3 | E125: . | F125: . | G125: 0.75 | H125: Toxicity | I125: 2 | J125: 2 | K125: isoniazid | L125: drug-induced liver injury;Toxic liver disease | M125: 44279 | N125: https://www.pharmgkb.org/clinicalAnnotation/1449003956 | O125: 1449003956 | P125: AA | Q125: Patients with the AA genotype who are taking isoniazid may have an increased risk of drug-induced liver injury as compared to patients with the AC or CC genotypes. However, another study found no association between this variant and the risk of drug-induced liver injury when taking isoniazid. Other genetic and clinical factors may also influence risk of drug-induced liver injury in patients taking isoniazid. | R125: .
A126: 1449003956 | B126: rs11125883 | C126: XPO1 | D126: 3 | E126: . | F126: . | G126: 0.75 | H126: Toxicity | I126: 2 | J126: 2 | K126: isoniazid | L126: drug-induced liver injury;Toxic liver disease | M126: 44279 | N126: https://www.pharmgkb.org/clinicalAnnotation/1449003956 | O126: 1449003956 | P126: AC | Q126: Patients with the AC genotype who are taking isoniazid may have decreased risk of drug-induced liver injury as compared to patients with the AA genotype. However, another study found no association between this variant and the risk of drug-induced liver injury when taking isoniazid. Other genetic and clinical factors may also influence risk of drug-induced liver injury in patients taking isoniazid. | R126: .
A127: 1449003956 | B127: rs11125883 | C127: XPO1 | D127: 3 | E127: . | F127: . | G127: 0.75 | H127: Toxicity | I127: 2 | J127: 2 | K127: isoniazid | L127: drug-induced liver injury;Toxic liver disease | M127: 44279 | N127: https://www.pharmgkb.org/clinicalAnnotation/1449003956 | O127: 1449003956 | P127: CC | Q127: Patients with the CC genotype who are taking isoniazid may have decreased risk of drug-induced liver injury as compared to patients with the AA genotype. However, another study found no association between this variant and the risk of drug-induced liver injury when taking isoniazid. Other genetic and clinical factors may also influence risk of drug-induced liver injury in patients taking isoniazid. | R127: .
A128: 1450935917 | B128: rs4430924 | C128: XPO1 | D128: 3 | E128: . | F128: . | G128: 2.25 | H128: Toxicity | I128: 1 | J128: 1 | K128: Drugs For Treatment Of Tuberculosis | L128: Drug Toxicity;Tuberculosis | M128: 44279 | N128: https://www.pharmgkb.org/clinicalAnnotation/1450935917 | O128: 1450935917 | P128: AA | Q128: Patients with the AA genotype may be at an increased risk of developing hepatotoxicity when treated with anti-tuberculosis (anti-TB) drugs as compared to patients with the AG or GG genotypes. Note that this association was only observed in a subgroup analysis of patients with probable hepatotoxicity. Other genetic and clinical factors may also affect a patient's risk of developing anti-TB drug-induced hepatotoxicity. | R128: .
A129: 1450935917 | B129: rs4430924 | C129: XPO1 | D129: 3 | E129: . | F129: . | G129: 2.25 | H129: Toxicity | I129: 1 | J129: 1 | K129: Drugs For Treatment Of Tuberculosis | L129: Drug Toxicity;Tuberculosis | M129: 44279 | N129: https://www.pharmgkb.org/clinicalAnnotation/1450935917 | O129: 1450935917 | P129: AG | Q129: Patients with the AG genotype may be at a decreased risk of developing hepatotoxicity when treated with anti-tuberculosis (anti-TB) drugs as compared to patients with the AA genotype. Note that this association was only observed in a subgroup analysis of patients with probable hepatotoxicity. Other genetic and clinical factors may also affect a patient's risk of developing anti-TB drug-induced hepatotoxicity. | R129: .
A130: 1450935917 | B130: rs4430924 | C130: XPO1 | D130: 3 | E130: . | F130: . | G130: 2.25 | H130: Toxicity | I130: 1 | J130: 1 | K130: Drugs For Treatment Of Tuberculosis | L130: Drug Toxicity;Tuberculosis | M130: 44279 | N130: https://www.pharmgkb.org/clinicalAnnotation/1450935917 | O130: 1450935917 | P130: GG | Q130: Patients with the GG genotype may be at a decreased risk of developing hepatotoxicity when treated with anti-tuberculosis (anti-TB) drugs as compared to patients with the AA genotype. Note that this association was only observed in a subgroup analysis of patients with probable hepatotoxicity. Other genetic and clinical factors may also affect a patient's risk of developing anti-TB drug-induced hepatotoxicity. | R130: .
A131: 1451261620 | B131: rs3788853 | C131: XPNPEP2 | D131: 2B | E131: . | F131: . | G131: 8.25 | H131: Toxicity | I131: 3 | J131: 3 | K131: Ace Inhibitors, Plain | L131: Angioedema | M131: 44279 | N131: https://www.pharmgkb.org/clinicalAnnotation/1451261620 | O131: 1451261620 | P131: A | Q131: Patients with one X-chromosome and the rs3788853 A genotype may have increased likelihood of angioedema when treated with ace inhibitors as compared to patients with the C or CC genotypes. Other genetic and clinical factors may also influence ace inhibitor associated angioedema. | R131: .
A132: 1451261620 | B132: rs3788853 | C132: XPNPEP2 | D132: 2B | E132: . | F132: . | G132: 8.25 | H132: Toxicity | I132: 3 | J132: 3 | K132: Ace Inhibitors, Plain | L132: Angioedema | M132: 44279 | N132: https://www.pharmgkb.org/clinicalAnnotation/1451261620 | O132: 1451261620 | P132: AA | Q132: Patients with two X-chromosomes and the rs3788853 AA genotype may have increased likelihood of angioedema when treated with ace inhibitors as compared to patients with the CC genotype. This gene is on the X chromosome therefore some individuals may have only one allele. Other genetic and clinical factors may also influence ace inhibitor associated angioedema. | R132: .
A133: 1451261620 | B133: rs3788853 | C133: XPNPEP2 | D133: 2B | E133: . | F133: . | G133: 8.25 | H133: Toxicity | I133: 3 | J133: 3 | K133: Ace Inhibitors, Plain | L133: Angioedema | M133: 44279 | N133: https://www.pharmgkb.org/clinicalAnnotation/1451261620 | O133: 1451261620 | P133: AC | Q133: Patients with two X-chromosomes and the rs3788853 AC genotype may have decreased likelihood of angioedema when treated with ace inhibitors as compared to patients with the A or AA genotype. This gene is on the X chromosome therefore some individuals may have only one allele. Other genetic and clinical factors may also influence ace inhibitor associated angioedema. | R133: .
A134: 1451261620 | B134: rs3788853 | C134: XPNPEP2 | D134: 2B | E134: . | F134: . | G134: 8.25 | H134: Toxicity | I134: 3 | J134: 3 | K134: Ace Inhibitors, Plain | L134: Angioedema | M134: 44279 | N134: https://www.pharmgkb.org/clinicalAnnotation/1451261620 | O134: 1451261620 | P134: C | Q134: Patients with one X-chromosome and the rs3788853 C genotype may have decreased likelihood of angioedema when treated with ace inhibitors as compared to patients with the A genotype. Other genetic and clinical factors may also influence ace inhibitor associated angioedema. | R134: .
A135: 1451261620 | B135: rs3788853 | C135: XPNPEP2 | D135: 2B | E135: . | F135: . | G135: 8.25 | H135: Toxicity | I135: 3 | J135: 3 | K135: Ace Inhibitors, Plain | L135: Angioedema | M135: 44279 | N135: https://www.pharmgkb.org/clinicalAnnotation/1451261620 | O135: 1451261620 | P135: CC | Q135: Patients with two X-chromosomes and the rs3788853 CC genotype may have decreased likelihood of angioedema when treated with ace inhibitors as compared to patients with the AA genotype. This gene is on the X chromosome therefore some individuals may have only one allele. Other genetic and clinical factors may also influence ace inhibitor associated angioedema. | R135: .
A136: 1449146785 | B136: rs2228000 | C136: XPC | D136: 3 | E136: . | F136: . | G136: 1.5 | H136: Toxicity | I136: 1 | J136: 2 | K136: Platinum compounds | L136: Carcinoma, Non-Small-Cell Lung;gastrointestinal toxicity;Hematologic Diseases;Leukopenia | M136: 44279 | N136: https://www.pharmgkb.org/clinicalAnnotation/1449146785 | O136: 1449146785 | P136: AA | Q136: Patients with non-small cell lung cancer and the AA genotype who are treated with platinum-based chemotherapy may have a decreased risk of hematologic toxicity, leukopenia, and GI toxicity as compared to patients with the GG genotype. There is no known association with risk of neutropenia, thrombocytopenia, or anemia. Other clinical and genetic factors may also influence risk of hematologic toxicity, leukopenia, and GI toxicity in patients with non-small cell lung cancer who are treated with platinum-based chemotherapy. | R136: .
A137: 1449146785 | B137: rs2228000 | C137: XPC | D137: 3 | E137: . | F137: . | G137: 1.5 | H137: Toxicity | I137: 1 | J137: 2 | K137: Platinum compounds | L137: Carcinoma, Non-Small-Cell Lung;gastrointestinal toxicity;Hematologic Diseases;Leukopenia | M137: 44279 | N137: https://www.pharmgkb.org/clinicalAnnotation/1449146785 | O137: 1449146785 | P137: AG | Q137: Patients with non-small cell lung cancer and the AG genotype who are treated with platinum-based chemotherapy may have a decreased risk of hematologic toxicity, leukopenia, and GI toxicity as compared to patients with the GG genotype. There is no known association with risk of neutropenia, thrombocytopenia, or anemia. Other clinical and genetic factors may also influence risk of hematologic toxicity, leukopenia, and GI toxicity in patients with non-small cell lung cancer who are treated with platinum-based chemotherapy. | R137: .
A138: 1449146785 | B138: rs2228000 | C138: XPC | D138: 3 | E138: . | F138: . | G138: 1.5 | H138: Toxicity | I138: 1 | J138: 2 | K138: Platinum compounds | L138: Carcinoma, Non-Small-Cell Lung;gastrointestinal toxicity;Hematologic Diseases;Leukopenia | M138: 44279 | N138: https://www.pharmgkb.org/clinicalAnnotation/1449146785 | O138: 1449146785 | P138: GG | Q138: Patients with non-small cell lung cancer and the GG genotype who are treated with platinum-based chemotherapy may have an increased risk of hematologic toxicity, leukopenia, and GI toxicity as compared to patients with the AA or AG genotypes. There is no known association with risk of neutropenia, thrombocytopenia, or anemia. Other clinical and genetic factors may also influence risk of hematologic toxicity, leukopenia, and GI toxicity in patients with non-small cell lung cancer who are treated with platinum-based chemotherapy. | R138: .
A139: 655386612 | B139: rs2228001 | C139: XPC | D139: 3 | E139: . | F139: . | G139: 0.75 | H139: Toxicity | I139: 2 | J139: 2 | K139: cisplatin | L139: Neoplasms;Osteosarcoma;Ototoxicity;Testicular Neoplasms | M139: 44279 | N139: https://www.pharmgkb.org/clinicalAnnotation/655386612 | O139: 655386612 | P139: GG | Q139: Patients with the GG genotype may have an increased risk for ototoxicity with cisplatin treatment as compared to patients with the TT genotype. However, another study failed to find this association. Other genetic and clinical factors may also influence a patient's risk for ototoxicity when treated with cisplatin. | R139: .
A140: 655386612 | B140: rs2228001 | C140: XPC | D140: 3 | E140: . | F140: . | G140: 0.75 | H140: Toxicity | I140: 2 | J140: 2 | K140: cisplatin | L140: Neoplasms;Osteosarcoma;Ototoxicity;Testicular Neoplasms | M140: 44279 | N140: https://www.pharmgkb.org/clinicalAnnotation/655386612 | O140: 655386612 | P140: GT | Q140: Patients with the GT genotype may have an increased risk for ototoxicity with cisplatin treatment as compared to patients with the TT genotype. However, another study failed to find this association. Other genetic and clinical factors may also influence a patient's risk for ototoxicity when treated with cisplatin. | R140: .
A141: 655386612 | B141: rs2228001 | C141: XPC | D141: 3 | E141: . | F141: . | G141: 0.75 | H141: Toxicity | I141: 2 | J141: 2 | K141: cisplatin | L141: Neoplasms;Osteosarcoma;Ototoxicity;Testicular Neoplasms | M141: 44279 | N141: https://www.pharmgkb.org/clinicalAnnotation/655386612 | O141: 655386612 | P141: TT | Q141: Patients with the TT genotype may have a decreased, but not non-existent, risk for ototoxicity with cisplatin treatment as compared to patients with the GG or GT genotypes. However, another study failed to find this association. Other genetic and clinical factors may also influence a patient's risk for ototoxicity when treated with cisplatin. | R141: .
A142: 1444666601 | B142: rs1800975 | C142: XPA | D142: 3 | E142: . | F142: . | G142: 2.25 | H142: Efficacy | I142: 1 | J142: 1 | K142: Platinum compounds | L142: Carcinoma, Non-Small-Cell Lung | M142: 44279 | N142: https://www.pharmgkb.org/clinicalAnnotation/1444666601 | O142: 1444666601 | P142: CC | Q142: Patients with the CC genotype and non-small-cell lung cancer may have a better response to treatment with platinum-based chemotherapy as compared to patients with the CT or TT genotype. Other genetic and clinical factors may also influence response to platinum-based chemotherapy. | R142: .
A143: 1444666601 | B143: rs1800975 | C143: XPA | D143: 3 | E143: . | F143: . | G143: 2.25 | H143: Efficacy | I143: 1 | J143: 1 | K143: Platinum compounds | L143: Carcinoma, Non-Small-Cell Lung | M143: 44279 | N143: https://www.pharmgkb.org/clinicalAnnotation/1444666601 | O143: 1444666601 | P143: CT | Q143: Patients with the CT genotype and non-small-cell lung cancer may have a poorer response to treatment with platinum-based chemotherapy as compared to patients with the CC genotype. Other genetic and clinical factors may also influence response to platinum-based chemotherapy. | R143: .
A144: 1444666601 | B144: rs1800975 | C144: XPA | D144: 3 | E144: . | F144: . | G144: 2.25 | H144: Efficacy | I144: 1 | J144: 1 | K144: Platinum compounds | L144: Carcinoma, Non-Small-Cell Lung | M144: 44279 | N144: https://www.pharmgkb.org/clinicalAnnotation/1444666601 | O144: 1444666601 | P144: TT | Q144: Patients with the TT genotype and non-small-cell lung cancer may have a poorer response to treatment with platinum-based chemotherapy as compared to patients with the CC genotype. Other genetic and clinical factors may also influence response to platinum-based chemotherapy. | R144: .
A145: 1450930536 | B145: rs7606603 | C145: XIRP2 | D145: 3 | E145: . | F145: . | G145: 2.25 | H145: Efficacy | I145: 1 | J145: 1 | K145: atenolol | L145: Hypertension | M145: 44279 | N145: https://www.pharmgkb.org/clinicalAnnotation/1450930536 | O145: 1450930536 | P145: CC | Q145: Patients with hypertension and the CC genotype may have a decreased systolic blood pressure response to atenolol as compared to patients with the TT genotype. Other genetic and clinical factors may also affect a patient's response to atenolol. | R145: .
A146: 1450930536 | B146: rs7606603 | C146: XIRP2 | D146: 3 | E146: . | F146: . | G146: 2.25 | H146: Efficacy | I146: 1 | J146: 1 | K146: atenolol | L146: Hypertension | M146: 44279 | N146: https://www.pharmgkb.org/clinicalAnnotation/1450930536 | O146: 1450930536 | P146: CT | Q146: Patients with hypertension and the CT genotype may have a decreased systolic blood pressure response to atenolol as compared to patients with the TT genotype. Other genetic and clinical factors may also affect a patient's response to atenolol. | R146: .
A147: 1450930536 | B147: rs7606603 | C147: XIRP2 | D147: 3 | E147: . | F147: . | G147: 2.25 | H147: Efficacy | I147: 1 | J147: 1 | K147: atenolol | L147: Hypertension | M147: 44279 | N147: https://www.pharmgkb.org/clinicalAnnotation/1450930536 | O147: 1450930536 | P147: TT | Q147: Patients with hypertension and the TT genotype may have an increased systolic blood pressure response to atenolol as compared to patients with the CC or CT genotypes. Other genetic and clinical factors may also affect a patient's response to atenolol. | R147: .
...

Sheet Sheet1
A1: ciprofloxacin | B1: {=_xlfn.XLOOKUP(A1,'clinical_ann_with_alleles_22.12'!$K$2:$K$15610,'clinical_ann_with_alleles_22.12'!$B$2:$B$15610,"Not Found")} -> Birmingham
A2: naproxen | B2: {=_xlfn.XLOOKUP(A2,'clinical_ann_with_alleles_22.12'!$K$2:$K$15610,'clinical_ann_with_alleles_22.12'!$B$2:$B$15610,"Not Found")} -> CYP2C9*2
A3: chloramphenicol | B3: {=_xlfn.XLOOKUP(A3,'clinical_ann_with_alleles_22.12'!$K$2:$K$15610,'clinical_ann_with_alleles_22.12'!$B$2:$B$15610,"Not Found")} -> G6PD B (reference)
A4: dimercaprol | B4: {=_xlfn.XLOOKUP(A4,'clinical_ann_with_alleles_22.12'!$K$2:$K$15610,'clinical_ann_with_alleles_22.12'!$B$2:$B$15610,"Not Found")} -> G6PD B (reference)
A5: nitrofurantoin | B5: {=_xlfn.XLOOKUP(A5,'clinical_ann_with_alleles_22.12'!$K$2:$K$15610,'clinical_ann_with_alleles_22.12'!$B$2:$B$15610,"Not Found")} -> G6PD B (reference) | C5: G6PD A- 202A_376G | D5: G6PD | E5: 3 | F5: . | G5: Tier 1 VIP | H5: 0.375 | I5: Toxicity | J5: 3 | K5: 3 | L5: nitrofurantoin | M5: Anemia, Hemolytic;Hemolysis | N5: 44943 | O5: https://www.pharmgkb.org/clinicalAnnotation/1184000346 | P5: 1184000346 | Q5: A-202A_376G/B (reference) | R5: Female patients with the A-202A_376G/B (reference) diplotype (heterozygous for the G6PD A- variant) who are treated with nitrofurantoin may have a varying degree of G6PD deficient red blood cells and an unknown risk of hemolysis as compared to patients with the A-202A_376G/A-202A_376G or B/B diplotype. Please note: all studies reported an association with G6PD deficiency but did not genotype or characterize the G6PD variant, here we are representing this association under the A- variant which is associated with G6PD deficiency, with the B (reference) haplotype representing G6PD non-deficient. Other genetic and clinical factors may also influence a patient's risk of drug-induced hemolysis.
A6: pegloticase | B6: {=_xlfn.XLOOKUP(A6,'clinical_ann_with_alleles_22.12'!$K$2:$K$15610,'clinical_ann_with_alleles_22.12'!$B$2:$B$15610,"Not Found")} -> G6PD A- 202A_376G
A7: levetiracetam | B7: {=_xlfn.XLOOKUP(A7,'clinical_ann_with_alleles_22.12'!$K$2:$K$15610,'clinical_ann_with_alleles_22.12'!$B$2:$B$15610,"Not Found")} -> HLA-A*11:01
A8: trichloroethylene | B8: {=_xlfn.XLOOKUP(A8,'clinical_ann_with_alleles_22.12'!$K$2:$K$15610,'clinical_ann_with_alleles_22.12'!$B$2:$B$15610,"Not Found")} -> HLA-B*13:01
A9: acetazolamide | B9: {=_xlfn.XLOOKUP(A9,'clinical_ann_with_alleles_22.12'!$K$2:$K$15610,'clinical_ann_with_alleles_22.12'!$B$2:$B$15610,"Not Found")} -> HLA-B*59:01
A10: ticlopidine | B10: {=_xlfn.XLOOKUP(A10,'clinical_ann_with_alleles_22.12'!$K$2:$K$15610,'clinical_ann_with_alleles_22.12'!$B$2:$B$15610,"Not Found")} -> HLA-C*14:03
A11: lapatinib | B11: {=_xlfn.XLOOKUP(A11,'clinical_ann_with_alleles_22.12'!$K$2:$K$15610,'clinical_ann_with_alleles_22.12'!$B$2:$B$15610,"Not Found")} -> HLA-DRB1*07:01
A12: heparin | B12: {=_xlfn.XLOOKUP(A12,'clinical_ann_with_alleles_22.12'!$K$2:$K$15610,'clinical_ann_with_alleles_22.12'!$B$2:$B$15610,"Not Found")} -> HLA-DRB3*01:01
A13: amantadine | B13: {=_xlfn.XLOOKUP(A13,'clinical_ann_with_alleles_22.12'!$K$2:$K$15610,'clinical_ann_with_alleles_22.12'!$B$2:$B$15610,"Not Found")} -> Not Found | C13: rs622342 | D13: SLC22A1
A14: amoxicillin | B14: {=_xlfn.XLOOKUP(A14,'clinical_ann_with_alleles_22.12'!$K$2:$K$15610,'clinical_ann_with_alleles_22.12'!$B$2:$B$15610,"Not Found")} -> Not Found | C14: rs9274407 | D14: HLA-DQB1 | E14: 3 | F14: . | G14: . | H14: 0 | I14: Toxicity | J14: 1 | K14: 1 | L14: amoxicillin;clavulanate
A15: chlorambucil | B15: {=_xlfn.XLOOKUP(A15,'clinical_ann_with_alleles_22.12'!$K$2:$K$15610,'clinical_ann_with_alleles_22.12'!$B$2:$B$15610,"Not Found")} -> Not Found
A16: dexrazoxane | B16: {=_xlfn.XLOOKUP(A16,'clinical_ann_with_alleles_22.12'!$K$2:$K$15610,'clinical_ann_with_alleles_22.12'!$B$2:$B$15610,"Not Found")} -> Not Found
A17: artemether | B17: {=_xlfn.XLOOKUP(A17,'clinical_ann_with_alleles_22.12'!$K$2:$K$15610,'clinical_ann_with_alleles_22.12'!$B$2:$B$15610,"Not Found")} -> Not Found
A18: brivaracetam | B18: {=_xlfn.XLOOKUP(A18,'clinical_ann_with_alleles_22.12'!$K$2:$K$15610,'clinical_ann_with_alleles_22.12'!$B$2:$B$15610,"Not Found")} -> Not Found
A19: chlorthalidone | B19: {=_xlfn.XLOOKUP(A19,'clinical_ann_with_alleles_22.12'!$K$2:$K$15610,'clinical_ann_with_alleles_22.12'!$B$2:$B$15610,"Not Found")} -> Not Found
A20: cilostazol | B20: {=_xlfn.XLOOKUP(A20,'clinical_ann_with_alleles_22.12'!$K$2:$K$15610,'clinical_ann_with_alleles_22.12'!$B$2:$B$15610,"Not Found")} -> Not Found
A21: dextroamphetamine | B21: {=_xlfn.XLOOKUP(A21,'clinical_ann_with_alleles_22.12'!$K$2:$K$15610,'clinical_ann_with_alleles_22.12'!$B$2:$B$15610,"Not Found")} -> Not Found
A22: hydroxychloroquine | B22: {=_xlfn.XLOOKUP(A22,'clinical_ann_with_alleles_22.12'!$K$2:$K$15610,'clinical_ann_with_alleles_22.12'!$B$2:$B$15610,"Not Found")} -> Not Found
A23: interferon beta-1b | B23: {=_xlfn.XLOOKUP(A23,'clinical_ann_with_alleles_22.12'!$K$2:$K$15610,'clinical_ann_with_alleles_22.12'!$B$2:$B$15610,"Not Found")} -> Not Found
A24: ketamine | B24: {=_xlfn.XLOOKUP(A24,'clinical_ann_with_alleles_22.12'!$K$2:$K$15610,'clinical_ann_with_alleles_22.12'!$B$2:$B$15610,"Not Found")} -> Not Found
A25: maraviroc | B25: {=_xlfn.XLOOKUP(A25,'clinical_ann_with_alleles_22.12'!$K$2:$K$15610,'clinical_ann_with_alleles_22.12'!$B$2:$B$15610,"Not Found")} -> Not Found
A26: interferon alfa-2a recombinant | B26: {=_xlfn.XLOOKUP(A26,'clinical_ann_with_alleles_22.12'!$K$2:$K$15610,'clinical_ann_with_alleles_22.12'!$B$2:$B$15610,"Not Found")} -> Not Found
... A54: sulfinpyrazone | B54: {=_xlfn.XLOOKUP(A54,'clinical_ann_with_alleles_22.12'!$K$2:$K$15610,'clinical_ann_with_alleles_22.12'!$B$2:$B$15610,"Not Found")} -> rs72551330
